[2023-11-09 12:59:40,117 INFO] Application started
[2023-11-09 12:59:53,775 INFO] /start from 1476403327
[2023-11-09 12:59:56,773 INFO] /start from 1476403327
[2023-11-09 13:00:13,955 INFO] Application is stopping. This might take a moment.
[2023-11-09 13:00:13,955 INFO] Application.stop() complete
[2023-11-09 13:03:08,614 INFO] Application started
[2023-11-09 13:03:12,040 INFO] /start from 1476403327
[2023-11-09 13:03:13,788 INFO] /start from 1476403327
[2023-11-09 13:03:14,599 INFO] /start from 1476403327
[2023-11-09 13:03:15,314 INFO] /start from 1476403327
[2023-11-09 13:03:20,903 INFO] Application is stopping. This might take a moment.
[2023-11-09 13:03:20,903 INFO] Application.stop() complete
[2023-11-09 13:43:39,297 INFO] Application started
[2023-11-09 13:43:50,985 INFO] /start from 1476403327
[2023-11-09 13:48:07,954 ERROR] Error while getting Updates: httpx.ReadError: 
[2023-11-09 13:48:07,954 ERROR] Exception while handling an update:
Traceback (most recent call last):
  File "C:\Users\User\PycharmProjects\qarz_daftar\venv\lib\site-packages\httpcore\_exceptions.py", line 10, in map_exceptions
    yield
  File "C:\Users\User\PycharmProjects\qarz_daftar\venv\lib\site-packages\httpcore\_backends\anyio.py", line 34, in read
    return await self._stream.receive(max_bytes=max_bytes)
  File "C:\Users\User\PycharmProjects\qarz_daftar\venv\lib\site-packages\anyio\streams\tls.py", line 198, in receive
    data = await self._call_sslobject_method(self._ssl_object.read, max_bytes)
  File "C:\Users\User\PycharmProjects\qarz_daftar\venv\lib\site-packages\anyio\streams\tls.py", line 140, in _call_sslobject_method
    data = await self.transport_stream.receive()
  File "C:\Users\User\PycharmProjects\qarz_daftar\venv\lib\site-packages\anyio\_backends\_asyncio.py", line 1112, in receive
    raise self._protocol.exception from None
anyio.BrokenResourceError

The above exception was the direct cause of the following exception:

Traceback (most recent call last):
  File "C:\Users\User\PycharmProjects\qarz_daftar\venv\lib\site-packages\httpx\_transports\default.py", line 66, in map_httpcore_exceptions
    yield
  File "C:\Users\User\PycharmProjects\qarz_daftar\venv\lib\site-packages\httpx\_transports\default.py", line 366, in handle_async_request
    resp = await self._pool.handle_async_request(req)
  File "C:\Users\User\PycharmProjects\qarz_daftar\venv\lib\site-packages\httpcore\_async\connection_pool.py", line 268, in handle_async_request
    raise exc
  File "C:\Users\User\PycharmProjects\qarz_daftar\venv\lib\site-packages\httpcore\_async\connection_pool.py", line 251, in handle_async_request
    response = await connection.handle_async_request(request)
  File "C:\Users\User\PycharmProjects\qarz_daftar\venv\lib\site-packages\httpcore\_async\connection.py", line 103, in handle_async_request
    return await self._connection.handle_async_request(request)
  File "C:\Users\User\PycharmProjects\qarz_daftar\venv\lib\site-packages\httpcore\_async\http11.py", line 133, in handle_async_request
    raise exc
  File "C:\Users\User\PycharmProjects\qarz_daftar\venv\lib\site-packages\httpcore\_async\http11.py", line 111, in handle_async_request
    ) = await self._receive_response_headers(**kwargs)
  File "C:\Users\User\PycharmProjects\qarz_daftar\venv\lib\site-packages\httpcore\_async\http11.py", line 176, in _receive_response_headers
    event = await self._receive_event(timeout=timeout)
  File "C:\Users\User\PycharmProjects\qarz_daftar\venv\lib\site-packages\httpcore\_async\http11.py", line 212, in _receive_event
    data = await self._network_stream.read(
  File "C:\Users\User\PycharmProjects\qarz_daftar\venv\lib\site-packages\httpcore\_backends\anyio.py", line 31, in read
    with map_exceptions(exc_map):
  File "C:\Users\User\AppData\Local\Programs\Python\Python310\lib\contextlib.py", line 153, in __exit__
    self.gen.throw(typ, value, traceback)
  File "C:\Users\User\PycharmProjects\qarz_daftar\venv\lib\site-packages\httpcore\_exceptions.py", line 14, in map_exceptions
    raise to_exc(exc) from exc
httpcore.ReadError

The above exception was the direct cause of the following exception:

Traceback (most recent call last):
  File "C:\Users\User\PycharmProjects\qarz_daftar\venv\lib\site-packages\telegram\request\_httpxrequest.py", line 219, in do_request
    res = await self._client.request(
  File "C:\Users\User\PycharmProjects\qarz_daftar\venv\lib\site-packages\httpx\_client.py", line 1530, in request
    return await self.send(request, auth=auth, follow_redirects=follow_redirects)
  File "C:\Users\User\PycharmProjects\qarz_daftar\venv\lib\site-packages\httpx\_client.py", line 1617, in send
    response = await self._send_handling_auth(
  File "C:\Users\User\PycharmProjects\qarz_daftar\venv\lib\site-packages\httpx\_client.py", line 1645, in _send_handling_auth
    response = await self._send_handling_redirects(
  File "C:\Users\User\PycharmProjects\qarz_daftar\venv\lib\site-packages\httpx\_client.py", line 1682, in _send_handling_redirects
    response = await self._send_single_request(request)
  File "C:\Users\User\PycharmProjects\qarz_daftar\venv\lib\site-packages\httpx\_client.py", line 1719, in _send_single_request
    response = await transport.handle_async_request(request)
  File "C:\Users\User\PycharmProjects\qarz_daftar\venv\lib\site-packages\httpx\_transports\default.py", line 365, in handle_async_request
    with map_httpcore_exceptions():
  File "C:\Users\User\AppData\Local\Programs\Python\Python310\lib\contextlib.py", line 153, in __exit__
    self.gen.throw(typ, value, traceback)
  File "C:\Users\User\PycharmProjects\qarz_daftar\venv\lib\site-packages\httpx\_transports\default.py", line 83, in map_httpcore_exceptions
    raise mapped_exc(message) from exc
httpx.ReadError

The above exception was the direct cause of the following exception:

Traceback (most recent call last):
  File "C:\Users\User\PycharmProjects\qarz_daftar\venv\lib\site-packages\telegram\ext\_updater.py", line 640, in _network_loop_retry
    if not await action_cb():
  File "C:\Users\User\PycharmProjects\qarz_daftar\venv\lib\site-packages\telegram\ext\_updater.py", line 345, in polling_action_cb
    raise exc
  File "C:\Users\User\PycharmProjects\qarz_daftar\venv\lib\site-packages\telegram\ext\_updater.py", line 334, in polling_action_cb
    updates = await self.bot.get_updates(
  File "C:\Users\User\PycharmProjects\qarz_daftar\venv\lib\site-packages\telegram\ext\_extbot.py", line 565, in get_updates
    updates = await super().get_updates(
  File "C:\Users\User\PycharmProjects\qarz_daftar\venv\lib\site-packages\telegram\_bot.py", line 519, in decorator
    result = await func(self, *args, **kwargs)  # skipcq: PYL-E1102
  File "C:\Users\User\PycharmProjects\qarz_daftar\venv\lib\site-packages\telegram\_bot.py", line 3562, in get_updates
    await self._post(
  File "C:\Users\User\PycharmProjects\qarz_daftar\venv\lib\site-packages\telegram\_bot.py", line 607, in _post
    return await self._do_post(
  File "C:\Users\User\PycharmProjects\qarz_daftar\venv\lib\site-packages\telegram\ext\_extbot.py", line 347, in _do_post
    return await super()._do_post(
  File "C:\Users\User\PycharmProjects\qarz_daftar\venv\lib\site-packages\telegram\_bot.py", line 635, in _do_post
    return await request.post(
  File "C:\Users\User\PycharmProjects\qarz_daftar\venv\lib\site-packages\telegram\request\_baserequest.py", line 168, in post
    result = await self._request_wrapper(
  File "C:\Users\User\PycharmProjects\qarz_daftar\venv\lib\site-packages\telegram\request\_baserequest.py", line 288, in _request_wrapper
    raise exc
  File "C:\Users\User\PycharmProjects\qarz_daftar\venv\lib\site-packages\telegram\request\_baserequest.py", line 278, in _request_wrapper
    code, payload = await self.do_request(
  File "C:\Users\User\PycharmProjects\qarz_daftar\venv\lib\site-packages\telegram\request\_httpxrequest.py", line 243, in do_request
    raise NetworkError(f"httpx.{err.__class__.__name__}: {err}") from err
telegram.error.NetworkError: httpx.ReadError: 
[2023-11-09 13:48:07,983 ERROR] An error was raised and an uncaught error was raised while handling the error with an error_handler.
Traceback (most recent call last):
  File "C:\Users\User\PycharmProjects\qarz_daftar\venv\lib\site-packages\anyio\_core\_sockets.py", line 190, in connect_tcp
    addr_obj = ip_address(remote_host)
  File "C:\Users\User\AppData\Local\Programs\Python\Python310\lib\ipaddress.py", line 54, in ip_address
    raise ValueError(f'{address!r} does not appear to be an IPv4 or IPv6 address')
ValueError: 'api.telegram.org' does not appear to be an IPv4 or IPv6 address

During handling of the above exception, another exception occurred:

Traceback (most recent call last):
  File "C:\Users\User\PycharmProjects\qarz_daftar\venv\lib\site-packages\httpcore\_exceptions.py", line 10, in map_exceptions
    yield
  File "C:\Users\User\PycharmProjects\qarz_daftar\venv\lib\site-packages\httpcore\_backends\anyio.py", line 114, in connect_tcp
    stream: anyio.abc.ByteStream = await anyio.connect_tcp(
  File "C:\Users\User\PycharmProjects\qarz_daftar\venv\lib\site-packages\anyio\_core\_sockets.py", line 193, in connect_tcp
    gai_res = await getaddrinfo(
  File "C:\Users\User\AppData\Local\Programs\Python\Python310\lib\concurrent\futures\thread.py", line 58, in run
    result = self.fn(*self.args, **self.kwargs)
  File "C:\Users\User\AppData\Local\Programs\Python\Python310\lib\socket.py", line 955, in getaddrinfo
    for res in _socket.getaddrinfo(host, port, family, type, proto, flags):
socket.gaierror: [Errno 11001] getaddrinfo failed

The above exception was the direct cause of the following exception:

Traceback (most recent call last):
  File "C:\Users\User\PycharmProjects\qarz_daftar\venv\lib\site-packages\httpx\_transports\default.py", line 66, in map_httpcore_exceptions
    yield
  File "C:\Users\User\PycharmProjects\qarz_daftar\venv\lib\site-packages\httpx\_transports\default.py", line 366, in handle_async_request
    resp = await self._pool.handle_async_request(req)
  File "C:\Users\User\PycharmProjects\qarz_daftar\venv\lib\site-packages\httpcore\_async\connection_pool.py", line 268, in handle_async_request
    raise exc
  File "C:\Users\User\PycharmProjects\qarz_daftar\venv\lib\site-packages\httpcore\_async\connection_pool.py", line 251, in handle_async_request
    response = await connection.handle_async_request(request)
  File "C:\Users\User\PycharmProjects\qarz_daftar\venv\lib\site-packages\httpcore\_async\connection.py", line 99, in handle_async_request
    raise exc
  File "C:\Users\User\PycharmProjects\qarz_daftar\venv\lib\site-packages\httpcore\_async\connection.py", line 76, in handle_async_request
    stream = await self._connect(request)
  File "C:\Users\User\PycharmProjects\qarz_daftar\venv\lib\site-packages\httpcore\_async\connection.py", line 124, in _connect
    stream = await self._network_backend.connect_tcp(**kwargs)
  File "C:\Users\User\PycharmProjects\qarz_daftar\venv\lib\site-packages\httpcore\_backends\auto.py", line 30, in connect_tcp
    return await self._backend.connect_tcp(
  File "C:\Users\User\PycharmProjects\qarz_daftar\venv\lib\site-packages\httpcore\_backends\anyio.py", line 112, in connect_tcp
    with map_exceptions(exc_map):
  File "C:\Users\User\AppData\Local\Programs\Python\Python310\lib\contextlib.py", line 153, in __exit__
    self.gen.throw(typ, value, traceback)
  File "C:\Users\User\PycharmProjects\qarz_daftar\venv\lib\site-packages\httpcore\_exceptions.py", line 14, in map_exceptions
    raise to_exc(exc) from exc
httpcore.ConnectError: [Errno 11001] getaddrinfo failed

The above exception was the direct cause of the following exception:

Traceback (most recent call last):
  File "C:\Users\User\PycharmProjects\qarz_daftar\venv\lib\site-packages\telegram\request\_httpxrequest.py", line 219, in do_request
    res = await self._client.request(
  File "C:\Users\User\PycharmProjects\qarz_daftar\venv\lib\site-packages\httpx\_client.py", line 1530, in request
    return await self.send(request, auth=auth, follow_redirects=follow_redirects)
  File "C:\Users\User\PycharmProjects\qarz_daftar\venv\lib\site-packages\httpx\_client.py", line 1617, in send
    response = await self._send_handling_auth(
  File "C:\Users\User\PycharmProjects\qarz_daftar\venv\lib\site-packages\httpx\_client.py", line 1645, in _send_handling_auth
    response = await self._send_handling_redirects(
  File "C:\Users\User\PycharmProjects\qarz_daftar\venv\lib\site-packages\httpx\_client.py", line 1682, in _send_handling_redirects
    response = await self._send_single_request(request)
  File "C:\Users\User\PycharmProjects\qarz_daftar\venv\lib\site-packages\httpx\_client.py", line 1719, in _send_single_request
    response = await transport.handle_async_request(request)
  File "C:\Users\User\PycharmProjects\qarz_daftar\venv\lib\site-packages\httpx\_transports\default.py", line 365, in handle_async_request
    with map_httpcore_exceptions():
  File "C:\Users\User\AppData\Local\Programs\Python\Python310\lib\contextlib.py", line 153, in __exit__
    self.gen.throw(typ, value, traceback)
  File "C:\Users\User\PycharmProjects\qarz_daftar\venv\lib\site-packages\httpx\_transports\default.py", line 83, in map_httpcore_exceptions
    raise mapped_exc(message) from exc
httpx.ConnectError: [Errno 11001] getaddrinfo failed

The above exception was the direct cause of the following exception:

Traceback (most recent call last):
  File "C:\Users\User\PycharmProjects\qarz_daftar\venv\lib\site-packages\telegram\ext\_application.py", line 1751, in process_error
    await callback(update, context)
  File "C:\Users\User\PycharmProjects\qarz_daftar\main.py", line 55, in error_handler
    await context.bot.send_message(
  File "C:\Users\User\PycharmProjects\qarz_daftar\venv\lib\site-packages\telegram\ext\_extbot.py", line 2631, in send_message
    return await super().send_message(
  File "C:\Users\User\PycharmProjects\qarz_daftar\venv\lib\site-packages\telegram\_bot.py", line 519, in decorator
    result = await func(self, *args, **kwargs)  # skipcq: PYL-E1102
  File "C:\Users\User\PycharmProjects\qarz_daftar\venv\lib\site-packages\telegram\_bot.py", line 840, in send_message
    return await self._send_message(
  File "C:\Users\User\PycharmProjects\qarz_daftar\venv\lib\site-packages\telegram\ext\_extbot.py", line 529, in _send_message
    result = await super()._send_message(
  File "C:\Users\User\PycharmProjects\qarz_daftar\venv\lib\site-packages\telegram\_bot.py", line 697, in _send_message
    result = await self._post(
  File "C:\Users\User\PycharmProjects\qarz_daftar\venv\lib\site-packages\telegram\_bot.py", line 607, in _post
    return await self._do_post(
  File "C:\Users\User\PycharmProjects\qarz_daftar\venv\lib\site-packages\telegram\ext\_extbot.py", line 347, in _do_post
    return await super()._do_post(
  File "C:\Users\User\PycharmProjects\qarz_daftar\venv\lib\site-packages\telegram\_bot.py", line 635, in _do_post
    return await request.post(
  File "C:\Users\User\PycharmProjects\qarz_daftar\venv\lib\site-packages\telegram\request\_baserequest.py", line 168, in post
    result = await self._request_wrapper(
  File "C:\Users\User\PycharmProjects\qarz_daftar\venv\lib\site-packages\telegram\request\_baserequest.py", line 288, in _request_wrapper
    raise exc
  File "C:\Users\User\PycharmProjects\qarz_daftar\venv\lib\site-packages\telegram\request\_baserequest.py", line 278, in _request_wrapper
    code, payload = await self.do_request(
  File "C:\Users\User\PycharmProjects\qarz_daftar\venv\lib\site-packages\telegram\request\_httpxrequest.py", line 243, in do_request
    raise NetworkError(f"httpx.{err.__class__.__name__}: {err}") from err
telegram.error.NetworkError: httpx.ConnectError: [Errno 11001] getaddrinfo failed
[2023-11-09 14:11:35,129 ERROR] Error while getting Updates: httpx.ConnectError: [Errno 11001] getaddrinfo failed
[2023-11-09 14:11:35,129 ERROR] Exception while handling an update:
Traceback (most recent call last):
  File "C:\Users\User\PycharmProjects\qarz_daftar\venv\lib\site-packages\anyio\_core\_sockets.py", line 190, in connect_tcp
    addr_obj = ip_address(remote_host)
  File "C:\Users\User\AppData\Local\Programs\Python\Python310\lib\ipaddress.py", line 54, in ip_address
    raise ValueError(f'{address!r} does not appear to be an IPv4 or IPv6 address')
ValueError: 'api.telegram.org' does not appear to be an IPv4 or IPv6 address

During handling of the above exception, another exception occurred:

Traceback (most recent call last):
  File "C:\Users\User\PycharmProjects\qarz_daftar\venv\lib\site-packages\httpcore\_exceptions.py", line 10, in map_exceptions
    yield
  File "C:\Users\User\PycharmProjects\qarz_daftar\venv\lib\site-packages\httpcore\_backends\anyio.py", line 114, in connect_tcp
    stream: anyio.abc.ByteStream = await anyio.connect_tcp(
  File "C:\Users\User\PycharmProjects\qarz_daftar\venv\lib\site-packages\anyio\_core\_sockets.py", line 193, in connect_tcp
    gai_res = await getaddrinfo(
  File "C:\Users\User\AppData\Local\Programs\Python\Python310\lib\concurrent\futures\thread.py", line 58, in run
    result = self.fn(*self.args, **self.kwargs)
  File "C:\Users\User\AppData\Local\Programs\Python\Python310\lib\socket.py", line 955, in getaddrinfo
    for res in _socket.getaddrinfo(host, port, family, type, proto, flags):
socket.gaierror: [Errno 11001] getaddrinfo failed

The above exception was the direct cause of the following exception:

Traceback (most recent call last):
  File "C:\Users\User\PycharmProjects\qarz_daftar\venv\lib\site-packages\httpx\_transports\default.py", line 66, in map_httpcore_exceptions
    yield
  File "C:\Users\User\PycharmProjects\qarz_daftar\venv\lib\site-packages\httpx\_transports\default.py", line 366, in handle_async_request
    resp = await self._pool.handle_async_request(req)
  File "C:\Users\User\PycharmProjects\qarz_daftar\venv\lib\site-packages\httpcore\_async\connection_pool.py", line 268, in handle_async_request
    raise exc
  File "C:\Users\User\PycharmProjects\qarz_daftar\venv\lib\site-packages\httpcore\_async\connection_pool.py", line 251, in handle_async_request
    response = await connection.handle_async_request(request)
  File "C:\Users\User\PycharmProjects\qarz_daftar\venv\lib\site-packages\httpcore\_async\connection.py", line 99, in handle_async_request
    raise exc
  File "C:\Users\User\PycharmProjects\qarz_daftar\venv\lib\site-packages\httpcore\_async\connection.py", line 76, in handle_async_request
    stream = await self._connect(request)
  File "C:\Users\User\PycharmProjects\qarz_daftar\venv\lib\site-packages\httpcore\_async\connection.py", line 124, in _connect
    stream = await self._network_backend.connect_tcp(**kwargs)
  File "C:\Users\User\PycharmProjects\qarz_daftar\venv\lib\site-packages\httpcore\_backends\auto.py", line 30, in connect_tcp
    return await self._backend.connect_tcp(
  File "C:\Users\User\PycharmProjects\qarz_daftar\venv\lib\site-packages\httpcore\_backends\anyio.py", line 112, in connect_tcp
    with map_exceptions(exc_map):
  File "C:\Users\User\AppData\Local\Programs\Python\Python310\lib\contextlib.py", line 153, in __exit__
    self.gen.throw(typ, value, traceback)
  File "C:\Users\User\PycharmProjects\qarz_daftar\venv\lib\site-packages\httpcore\_exceptions.py", line 14, in map_exceptions
    raise to_exc(exc) from exc
httpcore.ConnectError: [Errno 11001] getaddrinfo failed

The above exception was the direct cause of the following exception:

Traceback (most recent call last):
  File "C:\Users\User\PycharmProjects\qarz_daftar\venv\lib\site-packages\telegram\request\_httpxrequest.py", line 219, in do_request
    res = await self._client.request(
  File "C:\Users\User\PycharmProjects\qarz_daftar\venv\lib\site-packages\httpx\_client.py", line 1530, in request
    return await self.send(request, auth=auth, follow_redirects=follow_redirects)
  File "C:\Users\User\PycharmProjects\qarz_daftar\venv\lib\site-packages\httpx\_client.py", line 1617, in send
    response = await self._send_handling_auth(
  File "C:\Users\User\PycharmProjects\qarz_daftar\venv\lib\site-packages\httpx\_client.py", line 1645, in _send_handling_auth
    response = await self._send_handling_redirects(
  File "C:\Users\User\PycharmProjects\qarz_daftar\venv\lib\site-packages\httpx\_client.py", line 1682, in _send_handling_redirects
    response = await self._send_single_request(request)
  File "C:\Users\User\PycharmProjects\qarz_daftar\venv\lib\site-packages\httpx\_client.py", line 1719, in _send_single_request
    response = await transport.handle_async_request(request)
  File "C:\Users\User\PycharmProjects\qarz_daftar\venv\lib\site-packages\httpx\_transports\default.py", line 365, in handle_async_request
    with map_httpcore_exceptions():
  File "C:\Users\User\AppData\Local\Programs\Python\Python310\lib\contextlib.py", line 153, in __exit__
    self.gen.throw(typ, value, traceback)
  File "C:\Users\User\PycharmProjects\qarz_daftar\venv\lib\site-packages\httpx\_transports\default.py", line 83, in map_httpcore_exceptions
    raise mapped_exc(message) from exc
httpx.ConnectError: [Errno 11001] getaddrinfo failed

The above exception was the direct cause of the following exception:

Traceback (most recent call last):
  File "C:\Users\User\PycharmProjects\qarz_daftar\venv\lib\site-packages\telegram\ext\_updater.py", line 640, in _network_loop_retry
    if not await action_cb():
  File "C:\Users\User\PycharmProjects\qarz_daftar\venv\lib\site-packages\telegram\ext\_updater.py", line 345, in polling_action_cb
    raise exc
  File "C:\Users\User\PycharmProjects\qarz_daftar\venv\lib\site-packages\telegram\ext\_updater.py", line 334, in polling_action_cb
    updates = await self.bot.get_updates(
  File "C:\Users\User\PycharmProjects\qarz_daftar\venv\lib\site-packages\telegram\ext\_extbot.py", line 565, in get_updates
    updates = await super().get_updates(
  File "C:\Users\User\PycharmProjects\qarz_daftar\venv\lib\site-packages\telegram\_bot.py", line 519, in decorator
    result = await func(self, *args, **kwargs)  # skipcq: PYL-E1102
  File "C:\Users\User\PycharmProjects\qarz_daftar\venv\lib\site-packages\telegram\_bot.py", line 3562, in get_updates
    await self._post(
  File "C:\Users\User\PycharmProjects\qarz_daftar\venv\lib\site-packages\telegram\_bot.py", line 607, in _post
    return await self._do_post(
  File "C:\Users\User\PycharmProjects\qarz_daftar\venv\lib\site-packages\telegram\ext\_extbot.py", line 347, in _do_post
    return await super()._do_post(
  File "C:\Users\User\PycharmProjects\qarz_daftar\venv\lib\site-packages\telegram\_bot.py", line 635, in _do_post
    return await request.post(
  File "C:\Users\User\PycharmProjects\qarz_daftar\venv\lib\site-packages\telegram\request\_baserequest.py", line 168, in post
    result = await self._request_wrapper(
  File "C:\Users\User\PycharmProjects\qarz_daftar\venv\lib\site-packages\telegram\request\_baserequest.py", line 288, in _request_wrapper
    raise exc
  File "C:\Users\User\PycharmProjects\qarz_daftar\venv\lib\site-packages\telegram\request\_baserequest.py", line 278, in _request_wrapper
    code, payload = await self.do_request(
  File "C:\Users\User\PycharmProjects\qarz_daftar\venv\lib\site-packages\telegram\request\_httpxrequest.py", line 243, in do_request
    raise NetworkError(f"httpx.{err.__class__.__name__}: {err}") from err
telegram.error.NetworkError: httpx.ConnectError: [Errno 11001] getaddrinfo failed
[2023-11-09 14:11:35,136 ERROR] An error was raised and an uncaught error was raised while handling the error with an error_handler.
Traceback (most recent call last):
  File "C:\Users\User\PycharmProjects\qarz_daftar\venv\lib\site-packages\anyio\_core\_sockets.py", line 190, in connect_tcp
    addr_obj = ip_address(remote_host)
  File "C:\Users\User\AppData\Local\Programs\Python\Python310\lib\ipaddress.py", line 54, in ip_address
    raise ValueError(f'{address!r} does not appear to be an IPv4 or IPv6 address')
ValueError: 'api.telegram.org' does not appear to be an IPv4 or IPv6 address

During handling of the above exception, another exception occurred:

Traceback (most recent call last):
  File "C:\Users\User\PycharmProjects\qarz_daftar\venv\lib\site-packages\httpcore\_exceptions.py", line 10, in map_exceptions
    yield
  File "C:\Users\User\PycharmProjects\qarz_daftar\venv\lib\site-packages\httpcore\_backends\anyio.py", line 114, in connect_tcp
    stream: anyio.abc.ByteStream = await anyio.connect_tcp(
  File "C:\Users\User\PycharmProjects\qarz_daftar\venv\lib\site-packages\anyio\_core\_sockets.py", line 193, in connect_tcp
    gai_res = await getaddrinfo(
  File "C:\Users\User\AppData\Local\Programs\Python\Python310\lib\concurrent\futures\thread.py", line 58, in run
    result = self.fn(*self.args, **self.kwargs)
  File "C:\Users\User\AppData\Local\Programs\Python\Python310\lib\socket.py", line 955, in getaddrinfo
    for res in _socket.getaddrinfo(host, port, family, type, proto, flags):
socket.gaierror: [Errno 11001] getaddrinfo failed

The above exception was the direct cause of the following exception:

Traceback (most recent call last):
  File "C:\Users\User\PycharmProjects\qarz_daftar\venv\lib\site-packages\httpx\_transports\default.py", line 66, in map_httpcore_exceptions
    yield
  File "C:\Users\User\PycharmProjects\qarz_daftar\venv\lib\site-packages\httpx\_transports\default.py", line 366, in handle_async_request
    resp = await self._pool.handle_async_request(req)
  File "C:\Users\User\PycharmProjects\qarz_daftar\venv\lib\site-packages\httpcore\_async\connection_pool.py", line 268, in handle_async_request
    raise exc
  File "C:\Users\User\PycharmProjects\qarz_daftar\venv\lib\site-packages\httpcore\_async\connection_pool.py", line 251, in handle_async_request
    response = await connection.handle_async_request(request)
  File "C:\Users\User\PycharmProjects\qarz_daftar\venv\lib\site-packages\httpcore\_async\connection.py", line 99, in handle_async_request
    raise exc
  File "C:\Users\User\PycharmProjects\qarz_daftar\venv\lib\site-packages\httpcore\_async\connection.py", line 76, in handle_async_request
    stream = await self._connect(request)
  File "C:\Users\User\PycharmProjects\qarz_daftar\venv\lib\site-packages\httpcore\_async\connection.py", line 124, in _connect
    stream = await self._network_backend.connect_tcp(**kwargs)
  File "C:\Users\User\PycharmProjects\qarz_daftar\venv\lib\site-packages\httpcore\_backends\auto.py", line 30, in connect_tcp
    return await self._backend.connect_tcp(
  File "C:\Users\User\PycharmProjects\qarz_daftar\venv\lib\site-packages\httpcore\_backends\anyio.py", line 112, in connect_tcp
    with map_exceptions(exc_map):
  File "C:\Users\User\AppData\Local\Programs\Python\Python310\lib\contextlib.py", line 153, in __exit__
    self.gen.throw(typ, value, traceback)
  File "C:\Users\User\PycharmProjects\qarz_daftar\venv\lib\site-packages\httpcore\_exceptions.py", line 14, in map_exceptions
    raise to_exc(exc) from exc
httpcore.ConnectError: [Errno 11001] getaddrinfo failed

The above exception was the direct cause of the following exception:

Traceback (most recent call last):
  File "C:\Users\User\PycharmProjects\qarz_daftar\venv\lib\site-packages\telegram\request\_httpxrequest.py", line 219, in do_request
    res = await self._client.request(
  File "C:\Users\User\PycharmProjects\qarz_daftar\venv\lib\site-packages\httpx\_client.py", line 1530, in request
    return await self.send(request, auth=auth, follow_redirects=follow_redirects)
  File "C:\Users\User\PycharmProjects\qarz_daftar\venv\lib\site-packages\httpx\_client.py", line 1617, in send
    response = await self._send_handling_auth(
  File "C:\Users\User\PycharmProjects\qarz_daftar\venv\lib\site-packages\httpx\_client.py", line 1645, in _send_handling_auth
    response = await self._send_handling_redirects(
  File "C:\Users\User\PycharmProjects\qarz_daftar\venv\lib\site-packages\httpx\_client.py", line 1682, in _send_handling_redirects
    response = await self._send_single_request(request)
  File "C:\Users\User\PycharmProjects\qarz_daftar\venv\lib\site-packages\httpx\_client.py", line 1719, in _send_single_request
    response = await transport.handle_async_request(request)
  File "C:\Users\User\PycharmProjects\qarz_daftar\venv\lib\site-packages\httpx\_transports\default.py", line 365, in handle_async_request
    with map_httpcore_exceptions():
  File "C:\Users\User\AppData\Local\Programs\Python\Python310\lib\contextlib.py", line 153, in __exit__
    self.gen.throw(typ, value, traceback)
  File "C:\Users\User\PycharmProjects\qarz_daftar\venv\lib\site-packages\httpx\_transports\default.py", line 83, in map_httpcore_exceptions
    raise mapped_exc(message) from exc
httpx.ConnectError: [Errno 11001] getaddrinfo failed

The above exception was the direct cause of the following exception:

Traceback (most recent call last):
  File "C:\Users\User\PycharmProjects\qarz_daftar\venv\lib\site-packages\telegram\ext\_application.py", line 1751, in process_error
    await callback(update, context)
  File "C:\Users\User\PycharmProjects\qarz_daftar\main.py", line 55, in error_handler
    await context.bot.send_message(
  File "C:\Users\User\PycharmProjects\qarz_daftar\venv\lib\site-packages\telegram\ext\_extbot.py", line 2631, in send_message
    return await super().send_message(
  File "C:\Users\User\PycharmProjects\qarz_daftar\venv\lib\site-packages\telegram\_bot.py", line 519, in decorator
    result = await func(self, *args, **kwargs)  # skipcq: PYL-E1102
  File "C:\Users\User\PycharmProjects\qarz_daftar\venv\lib\site-packages\telegram\_bot.py", line 840, in send_message
    return await self._send_message(
  File "C:\Users\User\PycharmProjects\qarz_daftar\venv\lib\site-packages\telegram\ext\_extbot.py", line 529, in _send_message
    result = await super()._send_message(
  File "C:\Users\User\PycharmProjects\qarz_daftar\venv\lib\site-packages\telegram\_bot.py", line 697, in _send_message
    result = await self._post(
  File "C:\Users\User\PycharmProjects\qarz_daftar\venv\lib\site-packages\telegram\_bot.py", line 607, in _post
    return await self._do_post(
  File "C:\Users\User\PycharmProjects\qarz_daftar\venv\lib\site-packages\telegram\ext\_extbot.py", line 347, in _do_post
    return await super()._do_post(
  File "C:\Users\User\PycharmProjects\qarz_daftar\venv\lib\site-packages\telegram\_bot.py", line 635, in _do_post
    return await request.post(
  File "C:\Users\User\PycharmProjects\qarz_daftar\venv\lib\site-packages\telegram\request\_baserequest.py", line 168, in post
    result = await self._request_wrapper(
  File "C:\Users\User\PycharmProjects\qarz_daftar\venv\lib\site-packages\telegram\request\_baserequest.py", line 288, in _request_wrapper
    raise exc
  File "C:\Users\User\PycharmProjects\qarz_daftar\venv\lib\site-packages\telegram\request\_baserequest.py", line 278, in _request_wrapper
    code, payload = await self.do_request(
  File "C:\Users\User\PycharmProjects\qarz_daftar\venv\lib\site-packages\telegram\request\_httpxrequest.py", line 243, in do_request
    raise NetworkError(f"httpx.{err.__class__.__name__}: {err}") from err
telegram.error.NetworkError: httpx.ConnectError: [Errno 11001] getaddrinfo failed
[2023-11-09 14:11:36,627 ERROR] Error while getting Updates: httpx.ConnectError: [Errno 11001] getaddrinfo failed
[2023-11-09 14:11:36,627 ERROR] Exception while handling an update:
Traceback (most recent call last):
  File "C:\Users\User\PycharmProjects\qarz_daftar\venv\lib\site-packages\anyio\_core\_sockets.py", line 190, in connect_tcp
    addr_obj = ip_address(remote_host)
  File "C:\Users\User\AppData\Local\Programs\Python\Python310\lib\ipaddress.py", line 54, in ip_address
    raise ValueError(f'{address!r} does not appear to be an IPv4 or IPv6 address')
ValueError: 'api.telegram.org' does not appear to be an IPv4 or IPv6 address

During handling of the above exception, another exception occurred:

Traceback (most recent call last):
  File "C:\Users\User\PycharmProjects\qarz_daftar\venv\lib\site-packages\httpcore\_exceptions.py", line 10, in map_exceptions
    yield
  File "C:\Users\User\PycharmProjects\qarz_daftar\venv\lib\site-packages\httpcore\_backends\anyio.py", line 114, in connect_tcp
    stream: anyio.abc.ByteStream = await anyio.connect_tcp(
  File "C:\Users\User\PycharmProjects\qarz_daftar\venv\lib\site-packages\anyio\_core\_sockets.py", line 193, in connect_tcp
    gai_res = await getaddrinfo(
  File "C:\Users\User\AppData\Local\Programs\Python\Python310\lib\concurrent\futures\thread.py", line 58, in run
    result = self.fn(*self.args, **self.kwargs)
  File "C:\Users\User\AppData\Local\Programs\Python\Python310\lib\socket.py", line 955, in getaddrinfo
    for res in _socket.getaddrinfo(host, port, family, type, proto, flags):
socket.gaierror: [Errno 11001] getaddrinfo failed

The above exception was the direct cause of the following exception:

Traceback (most recent call last):
  File "C:\Users\User\PycharmProjects\qarz_daftar\venv\lib\site-packages\httpx\_transports\default.py", line 66, in map_httpcore_exceptions
    yield
  File "C:\Users\User\PycharmProjects\qarz_daftar\venv\lib\site-packages\httpx\_transports\default.py", line 366, in handle_async_request
    resp = await self._pool.handle_async_request(req)
  File "C:\Users\User\PycharmProjects\qarz_daftar\venv\lib\site-packages\httpcore\_async\connection_pool.py", line 268, in handle_async_request
    raise exc
  File "C:\Users\User\PycharmProjects\qarz_daftar\venv\lib\site-packages\httpcore\_async\connection_pool.py", line 251, in handle_async_request
    response = await connection.handle_async_request(request)
  File "C:\Users\User\PycharmProjects\qarz_daftar\venv\lib\site-packages\httpcore\_async\connection.py", line 99, in handle_async_request
    raise exc
  File "C:\Users\User\PycharmProjects\qarz_daftar\venv\lib\site-packages\httpcore\_async\connection.py", line 76, in handle_async_request
    stream = await self._connect(request)
  File "C:\Users\User\PycharmProjects\qarz_daftar\venv\lib\site-packages\httpcore\_async\connection.py", line 124, in _connect
    stream = await self._network_backend.connect_tcp(**kwargs)
  File "C:\Users\User\PycharmProjects\qarz_daftar\venv\lib\site-packages\httpcore\_backends\auto.py", line 30, in connect_tcp
    return await self._backend.connect_tcp(
  File "C:\Users\User\PycharmProjects\qarz_daftar\venv\lib\site-packages\httpcore\_backends\anyio.py", line 112, in connect_tcp
    with map_exceptions(exc_map):
  File "C:\Users\User\AppData\Local\Programs\Python\Python310\lib\contextlib.py", line 153, in __exit__
    self.gen.throw(typ, value, traceback)
  File "C:\Users\User\PycharmProjects\qarz_daftar\venv\lib\site-packages\httpcore\_exceptions.py", line 14, in map_exceptions
    raise to_exc(exc) from exc
httpcore.ConnectError: [Errno 11001] getaddrinfo failed

The above exception was the direct cause of the following exception:

Traceback (most recent call last):
  File "C:\Users\User\PycharmProjects\qarz_daftar\venv\lib\site-packages\telegram\request\_httpxrequest.py", line 219, in do_request
    res = await self._client.request(
  File "C:\Users\User\PycharmProjects\qarz_daftar\venv\lib\site-packages\httpx\_client.py", line 1530, in request
    return await self.send(request, auth=auth, follow_redirects=follow_redirects)
  File "C:\Users\User\PycharmProjects\qarz_daftar\venv\lib\site-packages\httpx\_client.py", line 1617, in send
    response = await self._send_handling_auth(
  File "C:\Users\User\PycharmProjects\qarz_daftar\venv\lib\site-packages\httpx\_client.py", line 1645, in _send_handling_auth
    response = await self._send_handling_redirects(
  File "C:\Users\User\PycharmProjects\qarz_daftar\venv\lib\site-packages\httpx\_client.py", line 1682, in _send_handling_redirects
    response = await self._send_single_request(request)
  File "C:\Users\User\PycharmProjects\qarz_daftar\venv\lib\site-packages\httpx\_client.py", line 1719, in _send_single_request
    response = await transport.handle_async_request(request)
  File "C:\Users\User\PycharmProjects\qarz_daftar\venv\lib\site-packages\httpx\_transports\default.py", line 365, in handle_async_request
    with map_httpcore_exceptions():
  File "C:\Users\User\AppData\Local\Programs\Python\Python310\lib\contextlib.py", line 153, in __exit__
    self.gen.throw(typ, value, traceback)
  File "C:\Users\User\PycharmProjects\qarz_daftar\venv\lib\site-packages\httpx\_transports\default.py", line 83, in map_httpcore_exceptions
    raise mapped_exc(message) from exc
httpx.ConnectError: [Errno 11001] getaddrinfo failed

The above exception was the direct cause of the following exception:

Traceback (most recent call last):
  File "C:\Users\User\PycharmProjects\qarz_daftar\venv\lib\site-packages\telegram\ext\_updater.py", line 640, in _network_loop_retry
    if not await action_cb():
  File "C:\Users\User\PycharmProjects\qarz_daftar\venv\lib\site-packages\telegram\ext\_updater.py", line 345, in polling_action_cb
    raise exc
  File "C:\Users\User\PycharmProjects\qarz_daftar\venv\lib\site-packages\telegram\ext\_updater.py", line 334, in polling_action_cb
    updates = await self.bot.get_updates(
  File "C:\Users\User\PycharmProjects\qarz_daftar\venv\lib\site-packages\telegram\ext\_extbot.py", line 565, in get_updates
    updates = await super().get_updates(
  File "C:\Users\User\PycharmProjects\qarz_daftar\venv\lib\site-packages\telegram\_bot.py", line 519, in decorator
    result = await func(self, *args, **kwargs)  # skipcq: PYL-E1102
  File "C:\Users\User\PycharmProjects\qarz_daftar\venv\lib\site-packages\telegram\_bot.py", line 3562, in get_updates
    await self._post(
  File "C:\Users\User\PycharmProjects\qarz_daftar\venv\lib\site-packages\telegram\_bot.py", line 607, in _post
    return await self._do_post(
  File "C:\Users\User\PycharmProjects\qarz_daftar\venv\lib\site-packages\telegram\ext\_extbot.py", line 347, in _do_post
    return await super()._do_post(
  File "C:\Users\User\PycharmProjects\qarz_daftar\venv\lib\site-packages\telegram\_bot.py", line 635, in _do_post
    return await request.post(
  File "C:\Users\User\PycharmProjects\qarz_daftar\venv\lib\site-packages\telegram\request\_baserequest.py", line 168, in post
    result = await self._request_wrapper(
  File "C:\Users\User\PycharmProjects\qarz_daftar\venv\lib\site-packages\telegram\request\_baserequest.py", line 288, in _request_wrapper
    raise exc
  File "C:\Users\User\PycharmProjects\qarz_daftar\venv\lib\site-packages\telegram\request\_baserequest.py", line 278, in _request_wrapper
    code, payload = await self.do_request(
  File "C:\Users\User\PycharmProjects\qarz_daftar\venv\lib\site-packages\telegram\request\_httpxrequest.py", line 243, in do_request
    raise NetworkError(f"httpx.{err.__class__.__name__}: {err}") from err
telegram.error.NetworkError: httpx.ConnectError: [Errno 11001] getaddrinfo failed
[2023-11-09 14:11:36,634 ERROR] An error was raised and an uncaught error was raised while handling the error with an error_handler.
Traceback (most recent call last):
  File "C:\Users\User\PycharmProjects\qarz_daftar\venv\lib\site-packages\anyio\_core\_sockets.py", line 190, in connect_tcp
    addr_obj = ip_address(remote_host)
  File "C:\Users\User\AppData\Local\Programs\Python\Python310\lib\ipaddress.py", line 54, in ip_address
    raise ValueError(f'{address!r} does not appear to be an IPv4 or IPv6 address')
ValueError: 'api.telegram.org' does not appear to be an IPv4 or IPv6 address

During handling of the above exception, another exception occurred:

Traceback (most recent call last):
  File "C:\Users\User\PycharmProjects\qarz_daftar\venv\lib\site-packages\httpcore\_exceptions.py", line 10, in map_exceptions
    yield
  File "C:\Users\User\PycharmProjects\qarz_daftar\venv\lib\site-packages\httpcore\_backends\anyio.py", line 114, in connect_tcp
    stream: anyio.abc.ByteStream = await anyio.connect_tcp(
  File "C:\Users\User\PycharmProjects\qarz_daftar\venv\lib\site-packages\anyio\_core\_sockets.py", line 193, in connect_tcp
    gai_res = await getaddrinfo(
  File "C:\Users\User\AppData\Local\Programs\Python\Python310\lib\concurrent\futures\thread.py", line 58, in run
    result = self.fn(*self.args, **self.kwargs)
  File "C:\Users\User\AppData\Local\Programs\Python\Python310\lib\socket.py", line 955, in getaddrinfo
    for res in _socket.getaddrinfo(host, port, family, type, proto, flags):
socket.gaierror: [Errno 11001] getaddrinfo failed

The above exception was the direct cause of the following exception:

Traceback (most recent call last):
  File "C:\Users\User\PycharmProjects\qarz_daftar\venv\lib\site-packages\httpx\_transports\default.py", line 66, in map_httpcore_exceptions
    yield
  File "C:\Users\User\PycharmProjects\qarz_daftar\venv\lib\site-packages\httpx\_transports\default.py", line 366, in handle_async_request
    resp = await self._pool.handle_async_request(req)
  File "C:\Users\User\PycharmProjects\qarz_daftar\venv\lib\site-packages\httpcore\_async\connection_pool.py", line 268, in handle_async_request
    raise exc
  File "C:\Users\User\PycharmProjects\qarz_daftar\venv\lib\site-packages\httpcore\_async\connection_pool.py", line 251, in handle_async_request
    response = await connection.handle_async_request(request)
  File "C:\Users\User\PycharmProjects\qarz_daftar\venv\lib\site-packages\httpcore\_async\connection.py", line 99, in handle_async_request
    raise exc
  File "C:\Users\User\PycharmProjects\qarz_daftar\venv\lib\site-packages\httpcore\_async\connection.py", line 76, in handle_async_request
    stream = await self._connect(request)
  File "C:\Users\User\PycharmProjects\qarz_daftar\venv\lib\site-packages\httpcore\_async\connection.py", line 124, in _connect
    stream = await self._network_backend.connect_tcp(**kwargs)
  File "C:\Users\User\PycharmProjects\qarz_daftar\venv\lib\site-packages\httpcore\_backends\auto.py", line 30, in connect_tcp
    return await self._backend.connect_tcp(
  File "C:\Users\User\PycharmProjects\qarz_daftar\venv\lib\site-packages\httpcore\_backends\anyio.py", line 112, in connect_tcp
    with map_exceptions(exc_map):
  File "C:\Users\User\AppData\Local\Programs\Python\Python310\lib\contextlib.py", line 153, in __exit__
    self.gen.throw(typ, value, traceback)
  File "C:\Users\User\PycharmProjects\qarz_daftar\venv\lib\site-packages\httpcore\_exceptions.py", line 14, in map_exceptions
    raise to_exc(exc) from exc
httpcore.ConnectError: [Errno 11001] getaddrinfo failed

The above exception was the direct cause of the following exception:

Traceback (most recent call last):
  File "C:\Users\User\PycharmProjects\qarz_daftar\venv\lib\site-packages\telegram\request\_httpxrequest.py", line 219, in do_request
    res = await self._client.request(
  File "C:\Users\User\PycharmProjects\qarz_daftar\venv\lib\site-packages\httpx\_client.py", line 1530, in request
    return await self.send(request, auth=auth, follow_redirects=follow_redirects)
  File "C:\Users\User\PycharmProjects\qarz_daftar\venv\lib\site-packages\httpx\_client.py", line 1617, in send
    response = await self._send_handling_auth(
  File "C:\Users\User\PycharmProjects\qarz_daftar\venv\lib\site-packages\httpx\_client.py", line 1645, in _send_handling_auth
    response = await self._send_handling_redirects(
  File "C:\Users\User\PycharmProjects\qarz_daftar\venv\lib\site-packages\httpx\_client.py", line 1682, in _send_handling_redirects
    response = await self._send_single_request(request)
  File "C:\Users\User\PycharmProjects\qarz_daftar\venv\lib\site-packages\httpx\_client.py", line 1719, in _send_single_request
    response = await transport.handle_async_request(request)
  File "C:\Users\User\PycharmProjects\qarz_daftar\venv\lib\site-packages\httpx\_transports\default.py", line 365, in handle_async_request
    with map_httpcore_exceptions():
  File "C:\Users\User\AppData\Local\Programs\Python\Python310\lib\contextlib.py", line 153, in __exit__
    self.gen.throw(typ, value, traceback)
  File "C:\Users\User\PycharmProjects\qarz_daftar\venv\lib\site-packages\httpx\_transports\default.py", line 83, in map_httpcore_exceptions
    raise mapped_exc(message) from exc
httpx.ConnectError: [Errno 11001] getaddrinfo failed

The above exception was the direct cause of the following exception:

Traceback (most recent call last):
  File "C:\Users\User\PycharmProjects\qarz_daftar\venv\lib\site-packages\telegram\ext\_application.py", line 1751, in process_error
    await callback(update, context)
  File "C:\Users\User\PycharmProjects\qarz_daftar\main.py", line 55, in error_handler
    await context.bot.send_message(
  File "C:\Users\User\PycharmProjects\qarz_daftar\venv\lib\site-packages\telegram\ext\_extbot.py", line 2631, in send_message
    return await super().send_message(
  File "C:\Users\User\PycharmProjects\qarz_daftar\venv\lib\site-packages\telegram\_bot.py", line 519, in decorator
    result = await func(self, *args, **kwargs)  # skipcq: PYL-E1102
  File "C:\Users\User\PycharmProjects\qarz_daftar\venv\lib\site-packages\telegram\_bot.py", line 840, in send_message
    return await self._send_message(
  File "C:\Users\User\PycharmProjects\qarz_daftar\venv\lib\site-packages\telegram\ext\_extbot.py", line 529, in _send_message
    result = await super()._send_message(
  File "C:\Users\User\PycharmProjects\qarz_daftar\venv\lib\site-packages\telegram\_bot.py", line 697, in _send_message
    result = await self._post(
  File "C:\Users\User\PycharmProjects\qarz_daftar\venv\lib\site-packages\telegram\_bot.py", line 607, in _post
    return await self._do_post(
  File "C:\Users\User\PycharmProjects\qarz_daftar\venv\lib\site-packages\telegram\ext\_extbot.py", line 347, in _do_post
    return await super()._do_post(
  File "C:\Users\User\PycharmProjects\qarz_daftar\venv\lib\site-packages\telegram\_bot.py", line 635, in _do_post
    return await request.post(
  File "C:\Users\User\PycharmProjects\qarz_daftar\venv\lib\site-packages\telegram\request\_baserequest.py", line 168, in post
    result = await self._request_wrapper(
  File "C:\Users\User\PycharmProjects\qarz_daftar\venv\lib\site-packages\telegram\request\_baserequest.py", line 288, in _request_wrapper
    raise exc
  File "C:\Users\User\PycharmProjects\qarz_daftar\venv\lib\site-packages\telegram\request\_baserequest.py", line 278, in _request_wrapper
    code, payload = await self.do_request(
  File "C:\Users\User\PycharmProjects\qarz_daftar\venv\lib\site-packages\telegram\request\_httpxrequest.py", line 243, in do_request
    raise NetworkError(f"httpx.{err.__class__.__name__}: {err}") from err
telegram.error.NetworkError: httpx.ConnectError: [Errno 11001] getaddrinfo failed
[2023-11-09 14:11:38,876 ERROR] Error while getting Updates: httpx.ConnectError: [Errno 11001] getaddrinfo failed
[2023-11-09 14:11:38,877 ERROR] Exception while handling an update:
Traceback (most recent call last):
  File "C:\Users\User\PycharmProjects\qarz_daftar\venv\lib\site-packages\anyio\_core\_sockets.py", line 190, in connect_tcp
    addr_obj = ip_address(remote_host)
  File "C:\Users\User\AppData\Local\Programs\Python\Python310\lib\ipaddress.py", line 54, in ip_address
    raise ValueError(f'{address!r} does not appear to be an IPv4 or IPv6 address')
ValueError: 'api.telegram.org' does not appear to be an IPv4 or IPv6 address

During handling of the above exception, another exception occurred:

Traceback (most recent call last):
  File "C:\Users\User\PycharmProjects\qarz_daftar\venv\lib\site-packages\httpcore\_exceptions.py", line 10, in map_exceptions
    yield
  File "C:\Users\User\PycharmProjects\qarz_daftar\venv\lib\site-packages\httpcore\_backends\anyio.py", line 114, in connect_tcp
    stream: anyio.abc.ByteStream = await anyio.connect_tcp(
  File "C:\Users\User\PycharmProjects\qarz_daftar\venv\lib\site-packages\anyio\_core\_sockets.py", line 193, in connect_tcp
    gai_res = await getaddrinfo(
  File "C:\Users\User\AppData\Local\Programs\Python\Python310\lib\concurrent\futures\thread.py", line 58, in run
    result = self.fn(*self.args, **self.kwargs)
  File "C:\Users\User\AppData\Local\Programs\Python\Python310\lib\socket.py", line 955, in getaddrinfo
    for res in _socket.getaddrinfo(host, port, family, type, proto, flags):
socket.gaierror: [Errno 11001] getaddrinfo failed

The above exception was the direct cause of the following exception:

Traceback (most recent call last):
  File "C:\Users\User\PycharmProjects\qarz_daftar\venv\lib\site-packages\httpx\_transports\default.py", line 66, in map_httpcore_exceptions
    yield
  File "C:\Users\User\PycharmProjects\qarz_daftar\venv\lib\site-packages\httpx\_transports\default.py", line 366, in handle_async_request
    resp = await self._pool.handle_async_request(req)
  File "C:\Users\User\PycharmProjects\qarz_daftar\venv\lib\site-packages\httpcore\_async\connection_pool.py", line 268, in handle_async_request
    raise exc
  File "C:\Users\User\PycharmProjects\qarz_daftar\venv\lib\site-packages\httpcore\_async\connection_pool.py", line 251, in handle_async_request
    response = await connection.handle_async_request(request)
  File "C:\Users\User\PycharmProjects\qarz_daftar\venv\lib\site-packages\httpcore\_async\connection.py", line 99, in handle_async_request
    raise exc
  File "C:\Users\User\PycharmProjects\qarz_daftar\venv\lib\site-packages\httpcore\_async\connection.py", line 76, in handle_async_request
    stream = await self._connect(request)
  File "C:\Users\User\PycharmProjects\qarz_daftar\venv\lib\site-packages\httpcore\_async\connection.py", line 124, in _connect
    stream = await self._network_backend.connect_tcp(**kwargs)
  File "C:\Users\User\PycharmProjects\qarz_daftar\venv\lib\site-packages\httpcore\_backends\auto.py", line 30, in connect_tcp
    return await self._backend.connect_tcp(
  File "C:\Users\User\PycharmProjects\qarz_daftar\venv\lib\site-packages\httpcore\_backends\anyio.py", line 112, in connect_tcp
    with map_exceptions(exc_map):
  File "C:\Users\User\AppData\Local\Programs\Python\Python310\lib\contextlib.py", line 153, in __exit__
    self.gen.throw(typ, value, traceback)
  File "C:\Users\User\PycharmProjects\qarz_daftar\venv\lib\site-packages\httpcore\_exceptions.py", line 14, in map_exceptions
    raise to_exc(exc) from exc
httpcore.ConnectError: [Errno 11001] getaddrinfo failed

The above exception was the direct cause of the following exception:

Traceback (most recent call last):
  File "C:\Users\User\PycharmProjects\qarz_daftar\venv\lib\site-packages\telegram\request\_httpxrequest.py", line 219, in do_request
    res = await self._client.request(
  File "C:\Users\User\PycharmProjects\qarz_daftar\venv\lib\site-packages\httpx\_client.py", line 1530, in request
    return await self.send(request, auth=auth, follow_redirects=follow_redirects)
  File "C:\Users\User\PycharmProjects\qarz_daftar\venv\lib\site-packages\httpx\_client.py", line 1617, in send
    response = await self._send_handling_auth(
  File "C:\Users\User\PycharmProjects\qarz_daftar\venv\lib\site-packages\httpx\_client.py", line 1645, in _send_handling_auth
    response = await self._send_handling_redirects(
  File "C:\Users\User\PycharmProjects\qarz_daftar\venv\lib\site-packages\httpx\_client.py", line 1682, in _send_handling_redirects
    response = await self._send_single_request(request)
  File "C:\Users\User\PycharmProjects\qarz_daftar\venv\lib\site-packages\httpx\_client.py", line 1719, in _send_single_request
    response = await transport.handle_async_request(request)
  File "C:\Users\User\PycharmProjects\qarz_daftar\venv\lib\site-packages\httpx\_transports\default.py", line 365, in handle_async_request
    with map_httpcore_exceptions():
  File "C:\Users\User\AppData\Local\Programs\Python\Python310\lib\contextlib.py", line 153, in __exit__
    self.gen.throw(typ, value, traceback)
  File "C:\Users\User\PycharmProjects\qarz_daftar\venv\lib\site-packages\httpx\_transports\default.py", line 83, in map_httpcore_exceptions
    raise mapped_exc(message) from exc
httpx.ConnectError: [Errno 11001] getaddrinfo failed

The above exception was the direct cause of the following exception:

Traceback (most recent call last):
  File "C:\Users\User\PycharmProjects\qarz_daftar\venv\lib\site-packages\telegram\ext\_updater.py", line 640, in _network_loop_retry
    if not await action_cb():
  File "C:\Users\User\PycharmProjects\qarz_daftar\venv\lib\site-packages\telegram\ext\_updater.py", line 345, in polling_action_cb
    raise exc
  File "C:\Users\User\PycharmProjects\qarz_daftar\venv\lib\site-packages\telegram\ext\_updater.py", line 334, in polling_action_cb
    updates = await self.bot.get_updates(
  File "C:\Users\User\PycharmProjects\qarz_daftar\venv\lib\site-packages\telegram\ext\_extbot.py", line 565, in get_updates
    updates = await super().get_updates(
  File "C:\Users\User\PycharmProjects\qarz_daftar\venv\lib\site-packages\telegram\_bot.py", line 519, in decorator
    result = await func(self, *args, **kwargs)  # skipcq: PYL-E1102
  File "C:\Users\User\PycharmProjects\qarz_daftar\venv\lib\site-packages\telegram\_bot.py", line 3562, in get_updates
    await self._post(
  File "C:\Users\User\PycharmProjects\qarz_daftar\venv\lib\site-packages\telegram\_bot.py", line 607, in _post
    return await self._do_post(
  File "C:\Users\User\PycharmProjects\qarz_daftar\venv\lib\site-packages\telegram\ext\_extbot.py", line 347, in _do_post
    return await super()._do_post(
  File "C:\Users\User\PycharmProjects\qarz_daftar\venv\lib\site-packages\telegram\_bot.py", line 635, in _do_post
    return await request.post(
  File "C:\Users\User\PycharmProjects\qarz_daftar\venv\lib\site-packages\telegram\request\_baserequest.py", line 168, in post
    result = await self._request_wrapper(
  File "C:\Users\User\PycharmProjects\qarz_daftar\venv\lib\site-packages\telegram\request\_baserequest.py", line 288, in _request_wrapper
    raise exc
  File "C:\Users\User\PycharmProjects\qarz_daftar\venv\lib\site-packages\telegram\request\_baserequest.py", line 278, in _request_wrapper
    code, payload = await self.do_request(
  File "C:\Users\User\PycharmProjects\qarz_daftar\venv\lib\site-packages\telegram\request\_httpxrequest.py", line 243, in do_request
    raise NetworkError(f"httpx.{err.__class__.__name__}: {err}") from err
telegram.error.NetworkError: httpx.ConnectError: [Errno 11001] getaddrinfo failed
[2023-11-09 14:11:38,884 ERROR] An error was raised and an uncaught error was raised while handling the error with an error_handler.
Traceback (most recent call last):
  File "C:\Users\User\PycharmProjects\qarz_daftar\venv\lib\site-packages\anyio\_core\_sockets.py", line 190, in connect_tcp
    addr_obj = ip_address(remote_host)
  File "C:\Users\User\AppData\Local\Programs\Python\Python310\lib\ipaddress.py", line 54, in ip_address
    raise ValueError(f'{address!r} does not appear to be an IPv4 or IPv6 address')
ValueError: 'api.telegram.org' does not appear to be an IPv4 or IPv6 address

During handling of the above exception, another exception occurred:

Traceback (most recent call last):
  File "C:\Users\User\PycharmProjects\qarz_daftar\venv\lib\site-packages\httpcore\_exceptions.py", line 10, in map_exceptions
    yield
  File "C:\Users\User\PycharmProjects\qarz_daftar\venv\lib\site-packages\httpcore\_backends\anyio.py", line 114, in connect_tcp
    stream: anyio.abc.ByteStream = await anyio.connect_tcp(
  File "C:\Users\User\PycharmProjects\qarz_daftar\venv\lib\site-packages\anyio\_core\_sockets.py", line 193, in connect_tcp
    gai_res = await getaddrinfo(
  File "C:\Users\User\AppData\Local\Programs\Python\Python310\lib\concurrent\futures\thread.py", line 58, in run
    result = self.fn(*self.args, **self.kwargs)
  File "C:\Users\User\AppData\Local\Programs\Python\Python310\lib\socket.py", line 955, in getaddrinfo
    for res in _socket.getaddrinfo(host, port, family, type, proto, flags):
socket.gaierror: [Errno 11001] getaddrinfo failed

The above exception was the direct cause of the following exception:

Traceback (most recent call last):
  File "C:\Users\User\PycharmProjects\qarz_daftar\venv\lib\site-packages\httpx\_transports\default.py", line 66, in map_httpcore_exceptions
    yield
  File "C:\Users\User\PycharmProjects\qarz_daftar\venv\lib\site-packages\httpx\_transports\default.py", line 366, in handle_async_request
    resp = await self._pool.handle_async_request(req)
  File "C:\Users\User\PycharmProjects\qarz_daftar\venv\lib\site-packages\httpcore\_async\connection_pool.py", line 268, in handle_async_request
    raise exc
  File "C:\Users\User\PycharmProjects\qarz_daftar\venv\lib\site-packages\httpcore\_async\connection_pool.py", line 251, in handle_async_request
    response = await connection.handle_async_request(request)
  File "C:\Users\User\PycharmProjects\qarz_daftar\venv\lib\site-packages\httpcore\_async\connection.py", line 99, in handle_async_request
    raise exc
  File "C:\Users\User\PycharmProjects\qarz_daftar\venv\lib\site-packages\httpcore\_async\connection.py", line 76, in handle_async_request
    stream = await self._connect(request)
  File "C:\Users\User\PycharmProjects\qarz_daftar\venv\lib\site-packages\httpcore\_async\connection.py", line 124, in _connect
    stream = await self._network_backend.connect_tcp(**kwargs)
  File "C:\Users\User\PycharmProjects\qarz_daftar\venv\lib\site-packages\httpcore\_backends\auto.py", line 30, in connect_tcp
    return await self._backend.connect_tcp(
  File "C:\Users\User\PycharmProjects\qarz_daftar\venv\lib\site-packages\httpcore\_backends\anyio.py", line 112, in connect_tcp
    with map_exceptions(exc_map):
  File "C:\Users\User\AppData\Local\Programs\Python\Python310\lib\contextlib.py", line 153, in __exit__
    self.gen.throw(typ, value, traceback)
  File "C:\Users\User\PycharmProjects\qarz_daftar\venv\lib\site-packages\httpcore\_exceptions.py", line 14, in map_exceptions
    raise to_exc(exc) from exc
httpcore.ConnectError: [Errno 11001] getaddrinfo failed

The above exception was the direct cause of the following exception:

Traceback (most recent call last):
  File "C:\Users\User\PycharmProjects\qarz_daftar\venv\lib\site-packages\telegram\request\_httpxrequest.py", line 219, in do_request
    res = await self._client.request(
  File "C:\Users\User\PycharmProjects\qarz_daftar\venv\lib\site-packages\httpx\_client.py", line 1530, in request
    return await self.send(request, auth=auth, follow_redirects=follow_redirects)
  File "C:\Users\User\PycharmProjects\qarz_daftar\venv\lib\site-packages\httpx\_client.py", line 1617, in send
    response = await self._send_handling_auth(
  File "C:\Users\User\PycharmProjects\qarz_daftar\venv\lib\site-packages\httpx\_client.py", line 1645, in _send_handling_auth
    response = await self._send_handling_redirects(
  File "C:\Users\User\PycharmProjects\qarz_daftar\venv\lib\site-packages\httpx\_client.py", line 1682, in _send_handling_redirects
    response = await self._send_single_request(request)
  File "C:\Users\User\PycharmProjects\qarz_daftar\venv\lib\site-packages\httpx\_client.py", line 1719, in _send_single_request
    response = await transport.handle_async_request(request)
  File "C:\Users\User\PycharmProjects\qarz_daftar\venv\lib\site-packages\httpx\_transports\default.py", line 365, in handle_async_request
    with map_httpcore_exceptions():
  File "C:\Users\User\AppData\Local\Programs\Python\Python310\lib\contextlib.py", line 153, in __exit__
    self.gen.throw(typ, value, traceback)
  File "C:\Users\User\PycharmProjects\qarz_daftar\venv\lib\site-packages\httpx\_transports\default.py", line 83, in map_httpcore_exceptions
    raise mapped_exc(message) from exc
httpx.ConnectError: [Errno 11001] getaddrinfo failed

The above exception was the direct cause of the following exception:

Traceback (most recent call last):
  File "C:\Users\User\PycharmProjects\qarz_daftar\venv\lib\site-packages\telegram\ext\_application.py", line 1751, in process_error
    await callback(update, context)
  File "C:\Users\User\PycharmProjects\qarz_daftar\main.py", line 55, in error_handler
    await context.bot.send_message(
  File "C:\Users\User\PycharmProjects\qarz_daftar\venv\lib\site-packages\telegram\ext\_extbot.py", line 2631, in send_message
    return await super().send_message(
  File "C:\Users\User\PycharmProjects\qarz_daftar\venv\lib\site-packages\telegram\_bot.py", line 519, in decorator
    result = await func(self, *args, **kwargs)  # skipcq: PYL-E1102
  File "C:\Users\User\PycharmProjects\qarz_daftar\venv\lib\site-packages\telegram\_bot.py", line 840, in send_message
    return await self._send_message(
  File "C:\Users\User\PycharmProjects\qarz_daftar\venv\lib\site-packages\telegram\ext\_extbot.py", line 529, in _send_message
    result = await super()._send_message(
  File "C:\Users\User\PycharmProjects\qarz_daftar\venv\lib\site-packages\telegram\_bot.py", line 697, in _send_message
    result = await self._post(
  File "C:\Users\User\PycharmProjects\qarz_daftar\venv\lib\site-packages\telegram\_bot.py", line 607, in _post
    return await self._do_post(
  File "C:\Users\User\PycharmProjects\qarz_daftar\venv\lib\site-packages\telegram\ext\_extbot.py", line 347, in _do_post
    return await super()._do_post(
  File "C:\Users\User\PycharmProjects\qarz_daftar\venv\lib\site-packages\telegram\_bot.py", line 635, in _do_post
    return await request.post(
  File "C:\Users\User\PycharmProjects\qarz_daftar\venv\lib\site-packages\telegram\request\_baserequest.py", line 168, in post
    result = await self._request_wrapper(
  File "C:\Users\User\PycharmProjects\qarz_daftar\venv\lib\site-packages\telegram\request\_baserequest.py", line 288, in _request_wrapper
    raise exc
  File "C:\Users\User\PycharmProjects\qarz_daftar\venv\lib\site-packages\telegram\request\_baserequest.py", line 278, in _request_wrapper
    code, payload = await self.do_request(
  File "C:\Users\User\PycharmProjects\qarz_daftar\venv\lib\site-packages\telegram\request\_httpxrequest.py", line 243, in do_request
    raise NetworkError(f"httpx.{err.__class__.__name__}: {err}") from err
telegram.error.NetworkError: httpx.ConnectError: [Errno 11001] getaddrinfo failed
[2023-11-09 14:11:51,743 INFO] Application is stopping. This might take a moment.
[2023-11-09 14:11:51,743 INFO] Application.stop() complete
[2023-11-09 14:23:38,028 INFO] Application started
[2023-11-09 14:24:18,443 INFO] Application is stopping. This might take a moment.
[2023-11-09 14:24:18,443 INFO] Application.stop() complete
[2023-11-09 14:24:19,842 INFO] Application started
[2023-11-09 14:29:40,161 INFO] Application is stopping. This might take a moment.
[2023-11-09 14:29:40,162 INFO] Application.stop() complete
[2023-11-09 14:29:42,649 INFO] Application started
[2023-11-09 14:29:47,385 INFO] /start from 1476403327
[2023-11-09 14:30:18,673 INFO] /start from 1476403327
[2023-11-09 14:32:41,498 ERROR] Task was destroyed but it is pending!
task: <Task pending name='Application:5581179119:update_fetcher' coro=<Application._update_fetcher() running at C:\Users\User\PycharmProjects\qarz_daftar\venv\lib\site-packages\telegram\ext\_application.py:1110> wait_for=<Future pending cb=[Task.task_wakeup()]>>
[2023-11-09 14:32:41,498 ERROR] Task was destroyed but it is pending!
task: <Task pending name='Application:5581179119:persistence_updater' coro=<Application._persistence_updater() running at C:\Users\User\PycharmProjects\qarz_daftar\venv\lib\site-packages\telegram\ext\_application.py:1503> wait_for=<Future pending cb=[Task.task_wakeup()]>>
[2023-11-09 14:32:41,499 ERROR] Task was destroyed but it is pending!
task: <Task pending name='Task-20' coro=<Event.wait() running at C:\Users\User\AppData\Local\Programs\Python\Python310\lib\asyncio\locks.py:214> wait_for=<Future pending cb=[Task.task_wakeup()]> cb=[_release_waiter(<Future pendi...ask_wakeup()]>)() at C:\Users\User\AppData\Local\Programs\Python\Python310\lib\asyncio\tasks.py:387]>
[2023-11-09 14:32:42,611 INFO] Application started
[2023-11-09 14:43:10,231 ERROR] Task was destroyed but it is pending!
task: <Task pending name='Application:5581179119:update_fetcher' coro=<Application._update_fetcher() running at C:\Users\User\PycharmProjects\qarz_daftar\venv\lib\site-packages\telegram\ext\_application.py:1110> wait_for=<Future pending cb=[Task.task_wakeup()]>>
[2023-11-09 14:43:10,231 ERROR] Task was destroyed but it is pending!
task: <Task pending name='Application:5581179119:persistence_updater' coro=<Application._persistence_updater() running at C:\Users\User\PycharmProjects\qarz_daftar\venv\lib\site-packages\telegram\ext\_application.py:1503> wait_for=<Future pending cb=[Task.task_wakeup()]>>
[2023-11-09 14:43:10,232 ERROR] Task was destroyed but it is pending!
task: <Task pending name='Task-35' coro=<Event.wait() running at C:\Users\User\AppData\Local\Programs\Python\Python310\lib\asyncio\locks.py:214> wait_for=<Future pending cb=[Task.task_wakeup()]> cb=[_release_waiter(<Future pendi...ask_wakeup()]>)() at C:\Users\User\AppData\Local\Programs\Python\Python310\lib\asyncio\tasks.py:387]>
[2023-11-09 14:43:11,763 INFO] Application started
[2023-11-09 14:43:34,867 ERROR] Task was destroyed but it is pending!
task: <Task pending name='Application:5581179119:update_fetcher' coro=<Application._update_fetcher() running at C:\Users\User\PycharmProjects\qarz_daftar\venv\lib\site-packages\telegram\ext\_application.py:1110> wait_for=<Future pending cb=[Task.task_wakeup()]>>
[2023-11-09 14:43:34,867 ERROR] Task was destroyed but it is pending!
task: <Task pending name='Application:5581179119:persistence_updater' coro=<Application._persistence_updater() running at C:\Users\User\PycharmProjects\qarz_daftar\venv\lib\site-packages\telegram\ext\_application.py:1503> wait_for=<Future pending cb=[Task.task_wakeup()]>>
[2023-11-09 14:43:34,868 ERROR] Task was destroyed but it is pending!
task: <Task pending name='Task-10' coro=<Event.wait() running at C:\Users\User\AppData\Local\Programs\Python\Python310\lib\asyncio\locks.py:214> wait_for=<Future pending cb=[Task.task_wakeup()]> cb=[_release_waiter(<Future pendi...ask_wakeup()]>)() at C:\Users\User\AppData\Local\Programs\Python\Python310\lib\asyncio\tasks.py:387]>
[2023-11-09 14:52:02,423 INFO] Application started
[2023-11-09 14:52:16,015 ERROR] Task was destroyed but it is pending!
task: <Task pending name='Application:5581179119:update_fetcher' coro=<Application._update_fetcher() running at C:\Users\User\PycharmProjects\qarz_daftar\venv\lib\site-packages\telegram\ext\_application.py:1110> wait_for=<Future pending cb=[Task.task_wakeup()]>>
[2023-11-09 14:52:16,015 ERROR] Task was destroyed but it is pending!
task: <Task pending name='Application:5581179119:persistence_updater' coro=<Application._persistence_updater() running at C:\Users\User\PycharmProjects\qarz_daftar\venv\lib\site-packages\telegram\ext\_application.py:1503> wait_for=<Future pending cb=[Task.task_wakeup()]>>
[2023-11-09 14:52:16,015 ERROR] Task was destroyed but it is pending!
task: <Task pending name='Task-10' coro=<Event.wait() running at C:\Users\User\AppData\Local\Programs\Python\Python310\lib\asyncio\locks.py:214> wait_for=<Future pending cb=[Task.task_wakeup()]> cb=[_release_waiter(<Future pendi...ask_wakeup()]>)() at C:\Users\User\AppData\Local\Programs\Python\Python310\lib\asyncio\tasks.py:387]>
[2023-11-09 15:06:12,869 INFO] Application started
[2023-11-09 15:06:17,467 INFO] Application is stopping. This might take a moment.
[2023-11-09 15:06:17,468 INFO] Application.stop() complete
[2023-11-09 15:06:58,995 INFO] Application started
[2023-11-09 15:07:03,590 ERROR] Task was destroyed but it is pending!
task: <Task pending name='Application:5581179119:update_fetcher' coro=<Application._update_fetcher() running at C:\Users\User\PycharmProjects\qarz_daftar\venv\lib\site-packages\telegram\ext\_application.py:1110> wait_for=<Future pending cb=[Task.task_wakeup()]>>
[2023-11-09 15:07:03,591 ERROR] Task was destroyed but it is pending!
task: <Task pending name='Application:5581179119:persistence_updater' coro=<Application._persistence_updater() running at C:\Users\User\PycharmProjects\qarz_daftar\venv\lib\site-packages\telegram\ext\_application.py:1503> wait_for=<Future pending cb=[Task.task_wakeup()]>>
[2023-11-09 15:07:03,591 ERROR] Task was destroyed but it is pending!
task: <Task pending name='Task-10' coro=<Event.wait() running at C:\Users\User\AppData\Local\Programs\Python\Python310\lib\asyncio\locks.py:214> wait_for=<Future pending cb=[Task.task_wakeup()]> cb=[_release_waiter(<Future pendi...ask_wakeup()]>)() at C:\Users\User\AppData\Local\Programs\Python\Python310\lib\asyncio\tasks.py:387]>
[2023-11-09 15:12:18,491 INFO] Application started
[2023-11-09 15:13:04,335 INFO] Application is stopping. This might take a moment.
[2023-11-09 15:13:04,336 INFO] Application.stop() complete
[2023-11-09 15:13:05,833 INFO] Application started
[2023-11-09 15:13:39,199 INFO] Application is stopping. This might take a moment.
[2023-11-09 15:13:39,199 INFO] Application.stop() complete
[2023-11-09 15:13:40,821 INFO] Application started
[2023-11-09 15:24:31,135 INFO] Application is stopping. This might take a moment.
[2023-11-09 15:24:31,136 INFO] Application.stop() complete
[2023-11-09 15:24:32,753 INFO] Application started
[2023-11-09 15:24:57,808 ERROR] Task was destroyed but it is pending!
task: <Task pending name='Application:5581179119:update_fetcher' coro=<Application._update_fetcher() running at C:\Users\User\PycharmProjects\qarz_daftar\venv\lib\site-packages\telegram\ext\_application.py:1110> wait_for=<Future pending cb=[Task.task_wakeup()]>>
[2023-11-09 15:24:57,808 ERROR] Task was destroyed but it is pending!
task: <Task pending name='Application:5581179119:persistence_updater' coro=<Application._persistence_updater() running at C:\Users\User\PycharmProjects\qarz_daftar\venv\lib\site-packages\telegram\ext\_application.py:1503> wait_for=<Future pending cb=[Task.task_wakeup()]>>
[2023-11-09 15:24:57,809 ERROR] Task was destroyed but it is pending!
task: <Task pending name='Task-10' coro=<Event.wait() running at C:\Users\User\AppData\Local\Programs\Python\Python310\lib\asyncio\locks.py:214> wait_for=<Future pending cb=[Task.task_wakeup()]> cb=[_release_waiter(<Future pendi...ask_wakeup()]>)() at C:\Users\User\AppData\Local\Programs\Python\Python310\lib\asyncio\tasks.py:387]>
[2023-11-09 15:25:09,638 INFO] Application started
[2023-11-09 15:39:34,681 INFO] Application is stopping. This might take a moment.
[2023-11-09 15:39:34,682 INFO] Application.stop() complete
[2023-11-09 15:39:36,309 INFO] Application started
[2023-11-09 15:44:19,548 INFO] Application is stopping. This might take a moment.
[2023-11-09 15:44:19,548 INFO] Application.stop() complete
[2023-11-09 15:44:21,126 INFO] Application started
[2023-11-09 15:48:40,312 INFO] Application is stopping. This might take a moment.
[2023-11-09 15:48:40,312 INFO] Application.stop() complete
[2023-11-09 15:48:41,912 INFO] Application started
[2023-11-09 15:50:13,834 INFO] Application is stopping. This might take a moment.
[2023-11-09 15:50:13,834 INFO] Application.stop() complete
[2023-11-09 15:50:16,613 INFO] Application started
[2023-11-09 15:53:45,548 INFO] Application is stopping. This might take a moment.
[2023-11-09 15:53:45,549 INFO] Application.stop() complete
[2023-11-09 15:53:46,965 INFO] Application started
[2023-11-09 15:55:17,139 ERROR] Task was destroyed but it is pending!
task: <Task pending name='Application:5581179119:update_fetcher' coro=<Application._update_fetcher() running at C:\Users\User\PycharmProjects\qarz_daftar\venv\lib\site-packages\telegram\ext\_application.py:1110> wait_for=<Future pending cb=[Task.task_wakeup()]>>
[2023-11-09 15:55:17,139 ERROR] Task was destroyed but it is pending!
task: <Task pending name='Application:5581179119:persistence_updater' coro=<Application._persistence_updater() running at C:\Users\User\PycharmProjects\qarz_daftar\venv\lib\site-packages\telegram\ext\_application.py:1503> wait_for=<Future pending cb=[Task.task_wakeup()]>>
[2023-11-09 15:55:17,140 ERROR] Task was destroyed but it is pending!
task: <Task pending name='Task-16' coro=<Event.wait() running at C:\Users\User\AppData\Local\Programs\Python\Python310\lib\asyncio\locks.py:214> wait_for=<Future pending cb=[Task.task_wakeup()]> cb=[_release_waiter(<Future pendi...ask_wakeup()]>)() at C:\Users\User\AppData\Local\Programs\Python\Python310\lib\asyncio\tasks.py:387]>
[2023-11-09 15:55:22,292 INFO] Application started
[2023-11-09 16:20:42,072 INFO] Application is stopping. This might take a moment.
[2023-11-09 16:20:42,073 INFO] Application.stop() complete
[2023-11-09 16:20:43,770 INFO] Application started
[2023-11-09 16:20:48,951 INFO] Application is stopping. This might take a moment.
[2023-11-09 16:20:48,951 INFO] Application.stop() complete
[2023-11-09 16:28:46,910 INFO] Application started
[2023-11-09 16:42:39,668 INFO] Application is stopping. This might take a moment.
[2023-11-09 16:42:39,669 INFO] Application.stop() complete
[2023-11-09 16:42:41,338 INFO] Application started
[2023-11-09 17:02:00,113 INFO] Application is stopping. This might take a moment.
[2023-11-09 17:02:00,114 INFO] Application.stop() complete
[2023-11-09 17:02:03,533 INFO] Application started
[2023-11-09 17:03:39,825 INFO] Application is stopping. This might take a moment.
[2023-11-09 17:03:39,825 INFO] Application.stop() complete
[2023-11-09 17:03:54,782 INFO] Application started
[2023-11-09 17:04:57,918 INFO] Application is stopping. This might take a moment.
[2023-11-09 17:04:57,918 INFO] Application.stop() complete
[2023-11-09 17:04:59,635 INFO] Application started
[2023-11-09 17:07:42,392 ERROR] Task was destroyed but it is pending!
task: <Task pending name='Application:5581179119:update_fetcher' coro=<Application._update_fetcher() running at C:\Users\User\PycharmProjects\qarz_daftar\venv\lib\site-packages\telegram\ext\_application.py:1110> wait_for=<Future pending cb=[Task.task_wakeup()]>>
[2023-11-09 17:07:42,393 ERROR] Task was destroyed but it is pending!
task: <Task pending name='Application:5581179119:persistence_updater' coro=<Application._persistence_updater() running at C:\Users\User\PycharmProjects\qarz_daftar\venv\lib\site-packages\telegram\ext\_application.py:1503> wait_for=<Future pending cb=[Task.task_wakeup()]>>
[2023-11-09 17:07:42,393 ERROR] Task was destroyed but it is pending!
task: <Task pending name='Task-23' coro=<Event.wait() running at C:\Users\User\AppData\Local\Programs\Python\Python310\lib\asyncio\locks.py:214> wait_for=<Future pending cb=[Task.task_wakeup()]> cb=[_release_waiter(<Future pendi...ask_wakeup()]>)() at C:\Users\User\AppData\Local\Programs\Python\Python310\lib\asyncio\tasks.py:387]>
[2023-11-09 17:07:43,463 INFO] Application started
[2023-11-09 17:10:35,874 INFO] Application is stopping. This might take a moment.
[2023-11-09 17:10:35,875 INFO] Application.stop() complete
[2023-11-09 17:10:37,497 INFO] Application started
[2023-11-09 17:31:52,188 INFO] Application is stopping. This might take a moment.
[2023-11-09 17:31:52,189 INFO] Application.stop() complete
[2023-11-09 17:31:53,899 INFO] Application started
[2023-11-09 17:33:27,763 INFO] Application is stopping. This might take a moment.
[2023-11-09 17:33:27,763 INFO] Application.stop() complete
[2023-11-09 17:33:29,304 INFO] Application started
[2023-11-09 17:37:01,274 INFO] Application is stopping. This might take a moment.
[2023-11-09 17:37:01,274 INFO] Application.stop() complete
[2023-11-09 17:37:02,455 INFO] Application started
[2023-11-09 17:38:38,687 ERROR] Task was destroyed but it is pending!
task: <Task pending name='Application:5581179119:update_fetcher' coro=<Application._update_fetcher() running at C:\Users\User\PycharmProjects\qarz_daftar\venv\lib\site-packages\telegram\ext\_application.py:1110> wait_for=<Future pending cb=[Task.task_wakeup()]>>
[2023-11-09 17:38:38,688 ERROR] Task was destroyed but it is pending!
task: <Task pending name='Application:5581179119:persistence_updater' coro=<Application._persistence_updater() running at C:\Users\User\PycharmProjects\qarz_daftar\venv\lib\site-packages\telegram\ext\_application.py:1503> wait_for=<Future pending cb=[Task.task_wakeup()]>>
[2023-11-09 17:38:38,688 ERROR] Task was destroyed but it is pending!
task: <Task pending name='Task-16' coro=<Event.wait() running at C:\Users\User\AppData\Local\Programs\Python\Python310\lib\asyncio\locks.py:214> wait_for=<Future pending cb=[Task.task_wakeup()]> cb=[_release_waiter(<Future pendi...ask_wakeup()]>)() at C:\Users\User\AppData\Local\Programs\Python\Python310\lib\asyncio\tasks.py:387]>
[2023-11-09 17:38:39,819 INFO] Application started
[2023-11-09 17:50:20,176 INFO] Application is stopping. This might take a moment.
[2023-11-09 17:50:20,177 INFO] Application.stop() complete
